Workbook

Sheet term one 2026
B1: SI No. | C1: First Name | D1: Middle Name | E1: Last Name | F1: Class Code | G1: Payment Code | H1: Guardian Phone | I1: fees due | J1: outstanding | K1: amount paid | L1: balance | M1: category | N1: colour category | O1: debt carried forward
B2: 1 | C2: Aleem | D2: Galugali | E2: Afan | F2: ELEPHANT | G2: 1010521012 | I2: 290000 | K2: =100000+100000+90000 -> 290000 | L2: =I2+J2-K2 -> 0
B3: 2 | C3: Mugambwa | D3: tyrone Tendo | E3: Mukasa | F3: ELEPHANT | G3: 1010607442 | I3: 290000 | K3: =200000+90000 -> 290000 | L3: =I3+J3-K3 -> 0
B4: 3 | C4: Nikky | D4: Nansubuga | F4: ELEPHANT | G4: 1010668240 | I4: 200000 | K4: =100000+100000 -> 200000 | L4: =I4+J4-K4 -> 0
B5: 4 | C5: Nabatanzi | D5: Bint Hamis | E5: Hannah | F5: ELEPHANT | G5: 1010680309 | I5: 270000 | K5: =150000+120000 -> 270000 | L5: =I5+J5-K5 -> 0
B6: 5 | C6: Sempela | D6: Paul | E6: Troy | F6: ELEPHANT | I6: =290000+300000 -> 590000 | K6: =590000 -> 590000 | L6: =I6+J6-K6 -> 0
B7: 6 | C7: Ruth | D7: Mirab | F7: ELEPHANT | I7: =200000 -> 200000 | K7: =150000+50000 -> 200000 | L7: =I7+J7-K7 -> 0
B8: 7 | C8: Nimurungi | D8: Alvin | E8: Sserugo | F8: ELEPHANT | I8: 80000 | K8: =80000 -> 80000 | L8: =I8+J8-K8 -> 0
B9: 8 | C9: Nalubega | D9: Samantha | E9: Zion | F9: ELEPHANT | I9: 80000 | K9: =40000 -> 40000 | L9: =I9+J9-K9 -> 40000
B10: 9 | C10: Nanyonga | D10: Pretty | E10: kiwanuka | F10: ELEPHANT | I10: 200000 | K10: =200000 -> 200000 | L10: =I10+J10-K10 -> 0
B11: 10 | C11: Adeke | D11: Dinah | F11: ELEPHANT | I11: 290000 | K11: =290000 -> 290000 | L11: =I11+J11-K11 -> 0
B12: 11 | C12: Namutebi | D12: Shukran | F12: ELEPHANT | I12: =260000 -> 260000 | K12: =100000+80000+60000+20000 -> 260000 | L12: =I12+J12-K12 -> 0 | M12: discount
B13: 12 | C13: Mukisa | D13: Daniel | F13: ELEPHANT | I13: =290000+250000 -> 540000 | K13: =540000 -> 540000 | L13: =I13+J13-K13 -> 0
A14: 7 | B14: 13 | C14: Wesonga | D14: Emmanuel | F14: ZEBRA | I14: =260000+100000 -> 360000 | K14: =100000+200000 -> 300000 | L14: =I14+J14-K14 -> 60000 | M14: vau user | N14: 260000
B15: 14 | C15: Aafruuz | D15: Mutambuli | E15: Mansoor | F15: ELEPHANT | I15: =100000 -> 100000 | K15: =50000+50000 -> 100000 | L15: =I15+J15-K15 -> 0
B16: 15 | C16: Mali | D16: Gracious | F16: ELEPHANT | I16: 80000 | K16: =80000 -> 80000 | L16: =I16+J16-K16 -> 0
B17: =1+B16 -> 16 | F17: ELEPHANT | L17: =I17+J17-K17 -> 0
B18: =1+B17 -> 17 | F18: ELEPHANT | L18: =I18+J18-K18 -> 0
B19: =1+B18 -> 18 | F19: ELEPHANT | L19: =I19+J19-K19 -> 0
B20: =1+B19 -> 19 | F20: ELEPHANT | L20: =I20+J20-K20 -> 0
B21: =1+B20 -> 20 | F21: ELEPHANT | L21: =I21+J21-K21 -> 0
D22: ZEBRA | I22: 0 | L22: =I22+J22-K22 -> 0
A23: 2 | B23: 1 | C23: Nansubuga | E23: Shuquran | F23: ZEBRA | G23: 1008799582 | I23: =290000 -> 290000 | K23: =150000+50000+50000+40000 -> 290000 | L23: =I23+J23-K23 -> 0
A24: 3 | B24: 2 | C24: Wamala | E24: Abdu | F24: ZEBRA | G24: 1008807850 | I24: =290000 -> 290000 | K24: =100000+59000+70000+60000 -> 289000 | L24: =I24+J24-K24 -> 1000
A25: 6 | B25: 3 | C25: Namwori | E25: Grace | F25: ZEBRA | G25: 1008878539 | I25: ='[1]1st term 2025'!J8 -> 80000 | K25: =80000 -> 80000 | L25: =I25+J25-K25 -> 0 | M25: teachers child
A26: 8 | B26: 4 | C26: Bakish | D26: Shakirah | E26: Muhammed | F26: ZEBRA | I26: ='[1]1st term 2025'!J10 -> 260000 | K26: =100000+160000 -> 260000 | L26: =I26+J26-K26 -> 0
A27: 9 | B27: 5 | C27: ivana | D27: Namutebi | F27: ZEBRA | I27: ='[1]1st term 2025'!J11 -> 80000 | K27: =50000+30000 -> 80000 | L27: =I27+J27-K27 -> 0 | M27: cook
A28: 11 | B28: 6 | C28: Ssenyondo | D28: Biden | E28: kakooza jovan | F28: ZEBRA | G28: 1009022251 | I28: =290000 -> 290000 | K28: =100000+100000 -> 200000 | L28: =I28+J28-K28 -> 90000
A29: 12 | B29: 7 | C29: Nakitende | D29: mercy | E29: Elizabeth | F29: ZEBRA | G29: 1008940427 | I29: =290000 -> 290000 | K29: =150000+50000+60000+30000+100000 -> 390000 | L29: =I29+J29-K29 -> -100000
A30: 15 | B30: 8 | C30: Muwanguzi | D30: Lael | E30: victor | F30: ZEBRA | G30: 1009102896 | I30: ='[1]1st term 2025'!J17+30000 -> 290000 | K30: =200000+90000 -> 290000 | L30: =I30+J30-K30 -> 0 | N30: 180000
A31: 17 | B31: 9 | C31: Gabriell | D31: Ayerango | E31: Grace | F31: ZEBRA | G31: 1009426740 | I31: =290000+50000 -> 340000 | K31: =120000+100000+120000 -> 340000 | L31: =I31+J31-K31 -> 0 | M31: reported in march
A32: 18 | B32: 10 | C32: Mulwanyi | E32: Chrizestom | F32: ZEBRA | G32: 1008793531 | I32: =230000 -> 230000 | K32: =50000+50000+50000 -> 150000 | L32: =I32+J32-K32 -> 80000 | M32: harmony atuheire 50000
B33: 11 | C33: Kaleb | D33: Myles | E33: Kolya | F33: ZEBRA | G33: 1009836293 | I33: =260000+30000 -> 290000 | K33: =270000+20000 -> 290000 | L33: =I33+J33-K33 -> 0
B34: 12 | C34: Princess | D34: Ayinebyona | E34: Nakato | F34: ZEBRA | I34: =260000+30000 -> 290000 | K34: =20000+20000+10000+10000+10000+20000+20000+15000+20000 -> 145000 | L34: =I34+J34-K34 -> 145000
B35: 13 | C35: Lauren | D35: Asio | E35: Malaika | F35: ZEBRA | I35: =290000+50000 -> 340000 | K35: =160000+180000 -> 340000 | L35: =I35+J35-K35 -> 0
L36: =I36+J36-K36 -> 0
D37: LION | I37: ='[1]1st term 2025'!J23 -> 0 | L37: =I37+J37-K37 -> 0
A38: 19 | B38: 1 | C38: Nakigozi | D38: Brovia | E38: Martha | F38: LION | G38: 1006914417 | I38: ='[1]1st term 2025'!J24 -> 255000 | K38: =200000+55000+70000 -> 325000 | L38: =I38+J38-K38 -> -70000 | M38: f
A39: 20 | B39: 2 | C39: Ssemakula | D39: Joseph | E39: Asher | F39: LION | G39: 1006914745 | I39: ='[1]1st term 2025'!J25 -> 80000 | K39: =80000 -> 80000 | L39: =I39+J39-K39 -> 0 | M39: f
A40: 22 | B40: 3 | C40: Kristian | D40: Pendo | E40: Ogola | F40: LION | G40: 1007134587 | I40: ='[1]1st term 2025'!J27 -> 260000 | K40: =260000 -> 260000 | L40: =I40+J40-K40 -> 0 | M40: f | N40: =L41+L44+#REF!+L45+#REF!+L49+#REF! -> #REF!
...

Sheet daily expense
A1: monthly expense per term
A2: item | B2: month | C2: quantity | D2: total | H2: income | I2: otm | J2: fees
A3: food | B3: 3200000 | C3: 3 | D3: =B3*C3 -> 9600000 | I3: 20000000 | J3: 45000000 | K3: =SUM(I3:J3) -> 65000000
A4: ingriendents | B4: 500000 | C4: 3 | D4: =B4*C4 -> 1500000
A5: tr special | B5: 120000 | C5: 3 | D5: =B5*C5 -> 360000
A6: boarding special meal | B6: 60000 | C6: 3 | D6: =B6*C6 -> 180000
A7: payee | B7: 460000 | C7: 3 | D7: =B7*C7 -> 1380000
A8: payee | B8: 110000 | C8: 1 | D8: =B8*C8 -> 110000 | H8: diff
A9: NSSF | B9: 1070000 | C9: 3 | D9: =B9*C9 -> 3210000
A10: NSSF | B10: 870000 | C10: 1 | D10: =B10*C10 -> 870000
A11: salaries | B11: 32163500 | C11: 1 | D11: =B11*C11 -> 32163500
A12: wages | B12: 200000 | C12: 3 | D12: =B12*C12 -> 600000
A13: firewood | B13: 500000 | C13: 3 | D13: =B13*C13 -> 1500000
A14: Electricity | B14: 1000000 | C14: 1 | D14: =B14*C14 -> 1000000
A15: Exams | B15: 660000 | C15: 1 | D15: =B15*C15 -> 660000
A16: mock | B16: 150000 | C16: 1 | D16: =B16*C16 -> 150000
A17: escorts staff | B17: 801500 | C17: 1 | D17: =B17*C17 -> 801500
A18: slashing | B18: 100000 | C18: 3 | D18: =B18*C18 -> 300000
A19: internet | B19: 150000 | C19: 3 | D19: =B19*C19 -> 450000
A20: airtime | B20: 50000 | C20: 3 | D20: =B20*C20 -> 150000
... A27: fuel | B27: 480000 | C27: 3 | D27: =B27*C27 -> 1440000
D28: =B28*C28 -> 0
D29: =B29*C29 -> 0
D30: =SUM(D3:D29) -> 66805000

Sheet school enrollment
A1: OFF-TU EDUCATION CENTRE MUKONO 2026
A2: TERM ONE ENROLLMENT 2026 | E2: TERM TWO ENROLLMENT 2026 | I2: TERM THREE ENROLLMENT 2026
B3: BOYS | C3: GIRLS | D3: TOTAL | F3: BOYS | G3: GIRLS | H3: TOTAL | J3: BOYS | K3: GIRLS | L3: TOTAL
A4: BABY | B4: 7 | C4: 7 | D4: =SUM(B4+C4) -> 14 | E4: BABY | F4: 8 | G4: 7 | H4: =SUM(F4+G4) -> 15 | I4: BABY
A5: MIDDLE | B5: 5 | C5: 8 | D5: =SUM(B5+C5) -> 13 | E5: MIDDLE | F5: 7 | G5: 7 | H5: =SUM(F5+G5) -> 14 | I5: MIDDLE
A6: TOP | B6: 7 | C6: 12 | D6: =SUM(B6+C6) -> 19 | E6: TOP | F6: 10 | G6: 11 | H6: =SUM(F6+G6) -> 21 | I6: TOP
A7: P.1 | B7: 20 | C7: 10 | D7: =SUM(B7+C7) -> 30 | E7: P.1 | F7: 16 | G7: 10 | H7: =SUM(F7+G7) -> 26 | I7: P.1
A8: P.2 | B8: 7 | C8: 9 | D8: =SUM(B8+C8) -> 16 | E8: P.2 | F8: 8 | G8: 13 | H8: =SUM(F8+G8) -> 21 | I8: P.2
A9: P.3 | B9: 10 | C9: 16 | D9: =SUM(B9+C9) -> 26 | E9: P.3 | F9: 9 | G9: 16 | H9: =SUM(F9+G9) -> 25 | I9: P.3
A10: P.4 | B10: 6 | C10: 14 | D10: =SUM(B10+C10) -> 20 | E10: P.4 | F10: 4 | G10: 14 | H10: =SUM(F10+G10) -> 18 | I10: P.4
A11: P.5 | B11: 10 | C11: 14 | D11: =SUM(B11+C11) -> 24 | E11: P.5 | F11: 10 | G11: 15 | H11: =SUM(F11+G11) -> 25 | I11: P.5
A12: P.6 | B12: 12 | C12: 8 | D12: =SUM(B12+C12) -> 20 | E12: P.6 | F12: 14 | G12: 7 | H12: =SUM(F12+G12) -> 21 | I12: P.6
A13: P.7 | B13: 12 | C13: 17 | D13: =SUM(B13+C13) -> 29 | E13: P.7 | F13: 14 | G13: 17 | H13: =SUM(F13+G13) -> 31 | I13: P.7
A14: TOTAL. NO | B14: =SUM(B4:B13) -> 96 | C14: =SUM(C4:C13) -> 115 | D14: =SUM(D4:D13) -> 211 | E14: TOTAL. NO | F14: =SUM(F4:F13) -> 100 | G14: =SUM(G4:G13) -> 117 | H14: =SUM(H4:H13) -> 217 | I14: TOTAL. NO
A16: OTEC TEACHERS ENROLLMENT
A17: MALE | B17: FEMALE | C17: TOTAL
A18: 4 | B18: 10 | C18: 14
A19: NURSERY | B19: LOWER | C19: UPPER
A20: 4 | B20: 6 | C20: 4

Sheet workbooks
D1: total | E1: no of books | F1: price | G1: total | H1: difference | I1: tt px | J1: sch px
A2: P.4 | B2: 6 | C2: 14 | D2: =SUM(B2+C2) -> 20 | E2: 5 | F2: 7000 | G2: =F2*E2 -> 35000 | H2: =J2-I2 -> 500000 | I2: =G2*D2 -> 700000 | J2: =D2*60000 -> 1200000
A3: P.5 | B3: 10 | C3: 14 | D3: =SUM(B3+C3) -> 24 | E3: 5 | F3: 7000 | G3: =F3*E3 -> 35000 | H3: =J3-I3 -> 600000 | I3: =G3*D3 -> 840000 | J3: =D3*60000 -> 1440000
A4: P.6 | B4: 12 | C4: 8 | D4: =SUM(B4+C4) -> 20 | E4: 5 | F4: 7000 | G4: =F4*E4 -> 35000 | H4: =J4-I4 -> 500000 | I4: =G4*D4 -> 700000 | J4: =D4*60000 -> 1200000
A5: P.7 | B5: 12 | C5: 17 | D5: =SUM(B5+C5) -> 29 | E5: 5 | F5: 7000 | G5: =F5*E5 -> 35000 | H5: =J5-I5 -> 725000 | I5: =G5*D5 -> 1015000 | J5: =D5*60000 -> 1740000
D7: =SUM(D2:D6) -> 93 | H7: =SUM(H2:H6) -> 2325000 | I7: =SUM(I2:I6) -> 3255000 | J7: =SUM(J2:J6) -> 5580000
B9: hw | C9: =D2*3500 -> 70000 | H9: =H7-C14 -> 1999500
B10: hw | C10: =D3*3500 -> 84000
B11: hw | C11: =D4*3500 -> 70000
B12: hw | C12: =D5*3500 -> 101500
C14: =SUM(C9:C13) -> 325500
C17: =D7*5 -> 465 | D17: =C17*1000 -> 465000 | F17: =30+15+26 -> 71 | G17: =F17*20000 -> 1420000
D22: =D7*20000 -> 1860000
D24: =D22/350000 -> 5.3142857

Sheet work book TERM 2
I1: PRICE OF WORK BOOK | K1: =60000 -> 60000
B2: TERM TWO WORK BOOKS
B3: NAME | C3: CLASS | D3: AMOUNT PAID | E3: BALANCE | F3: COST | G3: PROFIT | I3: CALCULATION
A4: 1 | B4: MUGABO JOSHUA | C4: P,6 | D4: 60000 | E4: =D4-$K$1 -> 0 | F4: 34800 | G4: =D4-F4 -> 25200 | I4: TOTAL | J4: SPENT | K4: =D109 -> 3650000
A5: =A4+1 -> 2 | B5: TOSUMA CHARLES | C5: P.4 | D5: 60000 | E5: =D5-$K$1 -> 0 | F5: 34800 | G5: =D5-F5 -> 25200 | I5: JEROX | J5: =300000 -> 300000
A6: =A5+1 -> 3 | B6: NASSALI ABIGAIL | C6: P.4 | D6: 60000 | E6: =D6-$K$1 -> 0 | F6: 34800 | G6: =D6-F6 -> 25200 | I6: PEACE | J6: 800000
A7: =A6+1 -> 4 | B7: MUGERWA SAMANTHA | C7: P.4 | D7: 60000 | E7: =D7-$K$1 -> 0 | F7: 34800 | G7: =D7-F7 -> 25200 | I7: PEACE | J7: 300000
A8: =A7+1 -> 5 | B8: TWABALYAKI PETER | C8: P.4 | D8: 60000 | E8: =D8-$K$1 -> 0 | F8: 34800 | G8: =D8-F8 -> 25200 | I8: PEACE | J8: 294400
A9: =A8+1 -> 6 | B9: RUKUNDO SHERINA | C9: P.4 | D9: 60000 | E9: =D9-$K$1 -> 0 | F9: 34800 | G9: =D9-F9 -> 25200 | I9: PEACE | J9: 60000
A10: =A9+1 -> 7 | B10: KYEYUNE GENESIS | C10: P.4 | D10: 60000 | E10: =D10-$K$1 -> 0 | F10: 34800 | G10: =D10-F10 -> 25200 | I10: SPIRO | J10: 1000000
A11: =A10+1 -> 8 | B11: AMODING DESTINY | C11: P.4 | D11: 60000 | E11: =D11-$K$1 -> 0 | F11: 34800 | G11: =D11-F11 -> 25200 | I11: INCOME DAY | J11: 476000
A12: =A11+1 -> 9 | B12: KASOWOLE HAIRAT | C12: P.5 | D12: 60000 | E12: =D12-$K$1 -> 0 | F12: 34800 | G12: =D12-F12 -> 25200
A13: =A12+1 -> 10 | B13: DDAMBA CALVIN | C13: P.5 | D13: 60000 | E13: =D13-$K$1 -> 0 | F13: 34800 | G13: =D13-F13 -> 25200
A14: =A13+1 -> 11 | B14: NANSUBUGA PRETTY | C14: P.5 | D14: 50000 | E14: =D14-$K$1 -> -10000 | F14: 34800 | G14: =D14-F14 -> 15200 | H14: SYS 10K
A15: =A14+1 -> 12 | B15: OMU BENJAMIN | C15: P.5 | D15: 60000 | E15: =D15-$K$1 -> 0 | F15: 34800 | G15: =D15-F15 -> 25200
A16: =A15+1 -> 13 | B16: MARAKA RUBI | C16: P.5 | D16: =30000+30000 -> 60000 | E16: =D16-$K$1 -> 0 | F16: 34800 | G16: =D16-F16 -> 25200
A17: =A16+1 -> 14 | B17: SSEMAKULA ALEYSHA | C17: P.5 | D17: 60000 | E17: =D17-$K$1 -> 0 | F17: 34800 | G17: =D17-F17 -> 25200
A18: =A17+1 -> 15 | B18: ISANKA FRANK | C18: P.5 | D18: 50000 | E18: =D18-$K$1 -> -10000 | F18: 34800 | G18: =D18-F18 -> 15200
A19: =A18+1 -> 16 | B19: BUGWATA HANNAH | C19: P.5 | D19: 60000 | E19: =D19-$K$1 -> 0 | F19: 34800 | G19: =D19-F19 -> 25200 | I19: TOTAL | J19: =SUM(J5:J18) -> 3230400
A20: =A19+1 -> 17 | B20: MEMBE SAMUEL | C20: P.5 | D20: 60000 | E20: =D20-$K$1 -> 0 | F20: 34800 | G20: =D20-F20 -> 25200 | I20: AVAILABLE | K20: =K4-J19 -> 419600
A21: =A20+1 -> 18 | B21: WAIRIMU OKIDI | C21: P.5 | D21: 30000 | E21: =D21-$K$1 -> -30000 | F21: 34800 | G21: =D21-F21 -> -4800
A22: =A21+1 -> 19 | B22: SHILLAH KAANA | C22: P.5 | D22: 60000 | E22: =D22-$K$1 -> 0 | F22: 34800 | G22: =D22-F22 -> 25200
A23: =A22+1 -> 20 | B23: NAMUGABI NISHA | C23: P.5 | D23: =30000+30000 -> 60000 | E23: =D23-$K$1 -> 0 | F23: 34800 | G23: =D23-F23 -> 25200
A24: =A23+1 -> 21 | B24: BIRUNGI PATIENCE | C24: P.5 | D24: 60000 | E24: =D24-$K$1 -> 0 | F24: 34800 | G24: =D24-F24 -> 25200
A25: =A24+1 -> 22 | B25: LWANGA AKRAM | C25: P.5 | D25: 60000 | E25: =D25-$K$1 -> 0 | F25: 34800 | G25: =D25-F25 -> 25200
A26: =A25+1 -> 23 | B26: MUKISA DESTINY | C26: P.5 | D26: 60000 | E26: =D26-$K$1 -> 0 | F26: 34800 | G26: =D26-F26 -> 25200
A27: =A26+1 -> 24 | B27: KATO MATOVU | C27: P.5 | D27: 60000 | E27: =D27-$K$1 -> 0 | F27: 34800 | G27: =D27-F27 -> 25200
A28: =A27+1 -> 25 | B28: WASSWA NSAMBA | C28: P.5 | D28: 60000 | E28: =D28-$K$1 -> 0 | F28: 34800 | G28: =D28-F28 -> 25200
A29: =A28+1 -> 26 | B29: NAMAGANDA PROSSY | C29: P.5 | D29: 60000 | E29: =D29-$K$1 -> 0 | F29: 34800 | G29: =D29-F29 -> 25200
A30: =A29+1 -> 27 | B30: KIRABO ANGEL | C30: P.5 | D30: 60000 | E30: =D30-$K$1 -> 0 | F30: 34800 | G30: =D30-F30 -> 25200
A31: =A30+1 -> 28 | B31: KYESSWA RONALD | C31: P.5 | D31: 60000 | E31: =D31-$K$1 -> 0 | F31: 34800 | G31: =D31-F31 -> 25200
A32: =A31+1 -> 29 | B32: KANSAZE GLORIA | C32: P.6 | D32: 60000 | E32: =D32-$K$1 -> 0 | F32: 34800 | G32: =D32-F32 -> 25200
A33: =A32+1 -> 30 | B33: KAYABULA CHRISTIAN | C33: P.6 | D33: 60000 | E33: =D33-$K$1 -> 0 | F33: 34800 | G33: =D33-F33 -> 25200
A34: =A33+1 -> 31 | B34: NABUTONO ALPHINE | C34: P.6 | D34: 60000 | E34: =D34-$K$1 -> 0 | F34: 34800 | G34: =D34-F34 -> 25200
A35: =A34+1 -> 32 | B35: BAHATI HUMPHREY | C35: P.6 | D35: 60000 | E35: =D35-$K$1 -> 0 | F35: 34800 | G35: =D35-F35 -> 25200
... A49: =A48+1 -> 46 | B49: NAMAGANDA VANESSA | C49: P.7 | D49: 40000 | E49: =D49-$K$1 -> -20000 | F49: 26000 | G49: =D49-F49 -> 14000
A50: =A49+1 -> 47 | B50: ATUHIRWE ALVIN | C50: P.7 | D50: 60000 | E50: =D50-$K$1 -> 0 | F50: 26000 | G50: =D50-F50 -> 34000 | M50: \
A51: =A50+1 -> 48 | B51: OKIRREAGAN | C51: P.7 | D51: 60000 | E51: =D51-$K$1 -> 0 | F51: 26000 | G51: =D51-F51 -> 34000
A52: =A51+1 -> 49 | B52: TUMUKUNDE ARNOLD | C52: P.7 | D52: 60000 | E52: =D52-$K$1 -> 0 | F52: 26000 | G52: =D52-F52 -> 34000
A53: =A52+1 -> 50 | B53: KOBUSINGYE ANITAH | C53: P.7 | D53: 60000 | E53: =D53-$K$1 -> 0 | F53: 26000 | G53: =D53-F53 -> 34000
...

Sheet library
I1: PRICE OF WORK BOOK | J1: LIB FEE | K1: 20000
B2: TERM TWO WORK BOOKS
B3: NAME | C3: CLASS | D3: AMOUNT PAID | E3: BALANCE | F3: COST | G3: PROFIT | I3: CALCULATION
A4: 1 | B4: KASOWOLE HAIRAT | C4: P.5 | D4: 20000 | I4: TOTAL | K4: =D109 -> 1740000
A5: =A4+1 -> 2 | B5: NAKAWUNDE CELLINE | C5: P.7 | D5: 20000 | I5: SPENT
A6: =A5+1 -> 3 | B6: DDAMBA CALVIN | C6: P.5 | D6: 20000 | I6: PRINTER | J6: 700000
A7: =A6+1 -> 4 | B7: NAMAGANDA VANESSA | C7: P.7 | D7: 20000 | I7: 2 COMPUTERS | J7: 800000
A8: =A7+1 -> 5 | B8: SSEKAJJA REUBEN | C8: P.1 | D8: 20000 | I8: GRAVEL | J8: 70000
A9: =A8+1 -> 6 | B9: NAMBUYA MALIKAH | C9: P.1 | D9: 20000 | I9: YAKA | J9: 150000
A10: =A9+1 -> 7 | B10: NYONYINTONO RAAIZ | C10: P.5 | D10: 20000
A11: =A10+1 -> 8 | B11: TOSUMA CHARLES | C11: P.4 | D11: 20000
A12: =A11+1 -> 9 | B12: NAMBI ESTHER | C12: P.2 | D12: 20000
A13: =A12+1 -> 10 | B13: KWAGALAKWE MELLISA | C13: P.3 | D13: 20000
A14: =A13+1 -> 11 | B14: FAUDEL NAJIB | C14: P.1 | D14: 20000
A15: =A14+1 -> 12 | B15: OMU BENJAMIN | C15: P.5 | D15: 20000
A16: =A15+1 -> 13 | B16: NASSALI ABIGAIL | C16: P.4 | D16: 20000
A17: =A16+1 -> 14 | B17: MUGERWA SAMANTHA | C17: P.4 | D17: 20000
A18: =A17+1 -> 15 | B18: WESONGA EMMANUEL | C18: MIDDLE | D18: 20000
A19: =A18+1 -> 16 | B19: SSEMAKULA ALEYSHA | C19: P.5 | D19: 20000 | I19: TOTAL: | J19: =SUM(J6:J18) -> 1720000
A20: =A19+1 -> 17 | B20: KISAKYE JOSHUA | C20: P.6 | D20: 20000 | I20: AVAILABLE | K20: =K4-J19 -> 20000
A21: =A20+1 -> 18 | B21: TUMUKUNDE ARNOLD | C21: P.7 | D21: 20000
A22: =A21+1 -> 19 | B22: KOBUSINGYE ANITAH | C22: P.7 | D22: 20000
A23: =A22+1 -> 20 | B23: SSEMAKULA WILSON | C23: P.6 | D23: 20000
A24: =A23+1 -> 21 | B24: TUSHEMEREIRWE ADRINE | C24: P.7 | D24: 20000
A25: =A24+1 -> 22 | B25: NABUTONO ALPHINE | C25: P.6 | D25: 20000
A26: =A25+1 -> 23 | B26: KUGUMA KEVIN | C26: P.6 | D26: 20000
A27: =A26+1 -> 24 | B27: BAHATI HUMPHREY | C27: P.6 | D27: 20000
A28: =A27+1 -> 25 | B28: ACHADU SERENA | C28: P.1 | D28: 20000
A29: =A28+1 -> 26 | B29: EKWAP EDGER | C29: P.2 | D29: 20000
A30: =A29+1 -> 27 | B30: MUKISA JEREMIAH | C30: P.1 | D30: 20000
A31: =A30+1 -> 28 | B31: MUKISA NATHANIEL | C31: P.1 | D31: 20000
A32: =A31+1 -> 29 | B32: LWANGA DESTINY | C32: P.1 | D32: 20000
... A57: =A56+1 -> 54 | B57: NAKAZIBWE DESIRE | C57: P.7 | D57: 20000
A58: =A57+1 -> 55 | B58: OTM GA | D58: 20000
A59: =A58+1 -> 56 | B59: OTM GA | D59: 20000
A60: =A59+1 -> 57 | B60: NAMBOOZO EMMANUEL | C60: P.1 | D60: 20000
A61: =A60+1 -> 58 | B61: MIREMBE ZURI | C61: P.1 | D61: 20000
A62: =A61+1 -> 59 | B62: MUKISA NATHANIEL | C62: P.1 | D62: 20000 | O62: 1
A63: =A62+1 -> 60 | B63: NITE KAWALA | C63: P.2 | D63: 20000
A64: =A63+1 -> 61 | B64: ADRINE TUSHEMEREIRWE | C64: P.3 | D64: 20000
...

Sheet UNIFORMS TERM TWO
A1: UNIFORMS TERM TWO
A2: DATE | B2: ITEM | C2: RECEIVED | D2: REFUND | E2: SPENT | F2: BALANCE

Sheet term two fees
B1: SI No. | C1: First Name | D1: Middle Name | E1: Last Name | F1: Class Code | G1: Payment Code | H1: Guardian Phone | I1: fees due | J1: outstanding | K1: amount paid | L1: balance | M1: category | N1: colour category | O1: debt carried forward
A2: 1 | B2: 1 | C2: Aleem | D2: Galugali | E2: Afan | F2: ELEPHANT | G2: 1010521012 | I2: 290000 | J2: ='term one 2026'!L2 -> 0 | K2: =100000+150000+40000 -> 290000 | L2: =I2+J2-K2 -> 0
A3: 2 | B3: 2 | C3: Mugambwa | D3: tyrone Tendo | E3: Mukasa | F3: ELEPHANT | G3: 1010607442 | I3: 290000 | J3: ='term one 2026'!L3 -> 0 | K3: =200000+90000 -> 290000 | L3: =I3+J3-K3 -> 0
A4: 3 | B4: 3 | C4: Nikky | D4: Nansubuga | F4: ELEPHANT | G4: 1010668240 | I4: 200000 | J4: ='term one 2026'!L4 -> 0 | K4: =100000+50000+50000 -> 200000 | L4: =I4+J4-K4 -> 0
A5: 4 | B5: 4 | C5: Nabatanzi | D5: Bint Hamis | E5: Hannah | F5: ELEPHANT | G5: 1010680309 | I5: 270000 | J5: ='term one 2026'!L5 -> 0 | K5: =200000+70000 -> 270000 | L5: =I5+J5-K5 -> 0
A6: 5 | B6: 5 | C6: Sempela | D6: Paul | E6: Troy | F6: ELEPHANT | I6: =290000+300000 -> 590000 | J6: ='term one 2026'!L6 -> 0 | K6: =590000 -> 590000 | L6: =I6+J6-K6 -> 0
A7: 6 | B7: 6 | C7: Ruth | D7: Mirab | F7: ELEPHANT | I7: =200000 -> 200000 | J7: ='term one 2026'!L7 -> 0 | K7: =200000 -> 200000
A8: 7 | B8: 7 | C8: Nimurungi | D8: Alvin | E8: Sserugo | F8: ELEPHANT | I8: 80000 | J8: ='term one 2026'!L8 -> 0 | L8: =I8+J8-K8 -> 80000
A9: 8 | B9: 8 | C9: Nalubega | D9: Samantha | E9: Zion | F9: ELEPHANT | I9: 80000 | J9: ='term one 2026'!L9 -> 40000 | L9: =I9+J9-K9 -> 120000
A10: 9 | B10: 9 | C10: Nanyonga | D10: Pretty | E10: kiwanuka | F10: ELEPHANT | I10: 200000 | J10: ='term one 2026'!L10 -> 0 | K10: =200000 -> 200000 | L10: =I10+J10-K10 -> 0
A11: 10 | B11: 10 | C11: Adeke | D11: Dinah | F11: ELEPHANT | I11: 290000 | J11: ='term one 2026'!L11 -> 0 | K11: =290000 -> 290000 | L11: =I11+J11-K11 -> 0
A12: 11 | B12: 11 | C12: Namutebi | D12: Shukran | F12: ELEPHANT | I12: =260000 -> 260000 | J12: ='term one 2026'!L12 -> 0 | K12: =100000 -> 100000 | L12: =I12+J12-K12 -> 160000 | M12: discount | N12: ream
A13: 12 | B13: 12 | C13: Mukisa | D13: Daniel | F13: ELEPHANT | I13: =290000+250000 -> 540000 | J13: ='term one 2026'!L13 -> 0 | K13: =540000 -> 540000 | L13: =I13+J13-K13 -> 0
A14: 13 | B14: 13 | C14: Wesonga | D14: Emmanuel | F14: ZEBRA | I14: =260000+100000 -> 360000 | J14: ='term one 2026'!L14 -> 60000 | K14: =100000+130000 -> 230000 | L14: =I14+J14-K14 -> 190000 | M14: vau user | N14: 260000
A15: 14 | B15: 14 | C15: Aafruuz | D15: Mutambuli | E15: Mansoor | F15: ELEPHANT | I15: 250000 | J15: ='term one 2026'!L15 -> 0 | K15: =100000 -> 100000 | L15: =I15+J15-K15 -> 150000
A16: 15 | B16: 15 | C16: Mali | D16: Gracious | F16: ELEPHANT | I16: 80000 | J16: ='term one 2026'!L16 -> 0 | L16: =I16+J16-K16 -> 80000
F17: ELEPHANT | J17: ='term one 2026'!L18 -> 0 | L17: =I17+J17-K17 -> 0
F18: ELEPHANT | J18: ='term one 2026'!L19 -> 0 | L18: =I18+J18-K18 -> 0
F19: ELEPHANT | J19: ='term one 2026'!L20 -> 0 | L19: =I19+J19-K19 -> 0
F20: ELEPHANT | J20: ='term one 2026'!L21 -> 0 | L20: =I20+J20-K20 -> 0
D21: ZEBRA | I21: 0 | J21: ='term one 2026'!L22 -> 0 | L21: =I21+J21-K21 -> 0
A22: 16 | B22: 1 | C22: Nansubuga | E22: Shuquran | F22: ZEBRA | G22: 1008799582 | I22: =290000 -> 290000 | J22: ='term one 2026'!L23 -> 0 | K22: =115000+50000+50000+40000+15000+20000 -> 290000 | L22: =I22+J22-K22 -> 0
A23: 17 | B23: 2 | C23: Wamala | E23: Abdu | F23: ZEBRA | G23: 1008807850 | I23: =290000 -> 290000 | J23: ='term one 2026'!L24 -> 1000 | K23: =101000+50000+59000 -> 210000 | L23: =I23+J23-K23 -> 81000
A24: 18 | B24: 3 | C24: Namwori | E24: Grace | F24: ZEBRA | G24: 1008878539 | I24: ='[1]1st term 2025'!J8 -> 80000 | J24: ='term one 2026'!L25 -> 0 | K24: =80000 -> 80000 | L24: =I24+J24-K24 -> 0 | M24: teachers child
A25: 19 | B25: 4 | C25: ivana | D25: Namutebi | F25: ZEBRA | I25: ='[1]1st term 2025'!J11 -> 80000 | J25: ='term one 2026'!L27 -> 0 | K25: =10000+50000 -> 60000 | L25: =I25+J25-K25 -> 20000 | M25: cook
A26: 20 | B26: 5 | C26: Ssenyondo | D26: Biden | E26: kakooza jovan | F26: ZEBRA | G26: 1009022251 | I26: =260000 -> 260000 | J26: ='term one 2026'!L28 -> 90000 | K26: =150000+100000+50000 -> 300000 | L26: =I26+J26-K26 -> 50000 | M26: ream
A27: 21 | B27: 6 | C27: Nakitende | D27: mercy | E27: Elizabeth | F27: ZEBRA | G27: 1008940427 | I27: =290000 -> 290000 | J27: ='term one 2026'!L29 -> -100000 | K27: =150000+40000 -> 190000 | L27: =I27+J27-K27 -> 0
A28: 22 | B28: 7 | C28: Muwanguzi | D28: Lael | E28: victor | F28: ZEBRA | G28: 1009102896 | I28: ='[1]1st term 2025'!J17+30000 -> 290000 | J28: ='term one 2026'!L30 -> 0 | K28: =290000 -> 290000 | L28: =I28+J28-K28 -> 0
A29: 23 | B29: 8 | C29: Gabriell | D29: Ayerango | E29: Grace | F29: ZEBRA | G29: 1009426740 | I29: =290000+60000+60000 -> 410000 | J29: ='term one 2026'!L31 -> 0 | K29: =130000+100000+180000 -> 410000 | L29: =I29+J29-K29 -> 0 | M29: reported in march
A30: 24 | B30: 9 | C30: Mulwanyi | E30: Chrizestom | F30: ZEBRA | G30: 1008793531 | I30: =220000 -> 220000 | J30: 0 | K30: =50000+30000 -> 80000 | L30: =I30+J30-K30 -> 140000
A31: 25 | B31: 10 | C31: Kaleb | D31: Myles | E31: Kolya | F31: ZEBRA | G31: 1009836293 | I31: =260000+30000 -> 290000 | J31: ='term one 2026'!L33 -> 0 | K31: =20000+270000 -> 290000 | L31: =I31+J31-K31 -> 0
A32: 26 | B32: 11 | C32: Princess | D32: Ayinebyona | E32: Nakato | F32: ZEBRA | I32: =260000+30000 -> 290000 | J32: ='term one 2026'!L34 -> 145000 | K32: =80000+100000+35000 -> 215000 | L32: =I32+J32-K32 -> 220000
A33: 27 | B33: 12 | C33: Lauren | D33: Asio | E33: Malaika | F33: ZEBRA | I33: =290000+50000 -> 340000 | J33: ='term one 2026'!L35 -> 0 | K33: =340000 -> 340000 | L33: =I33+J33-K33 -> 0
A34: 28 | B34: 13 | C34: Alvin | D34: Mutebi | F34: ZEBRA | I34: =250000 -> 250000 | J34: ='term one 2026'!L36 -> 0 | K34: =130000+30000+35000+55000 -> 250000 | L34: =I34+J34-K34 -> 0 | M34: escorts
A35: 29 | B35: 14 | C35: Ntambi | D35: Ramos | E35: Kabenge | F35: ZEBRA | I35: =250000+50000 -> 300000 | K35: =100000+50000+150000 -> 300000 | L35: =I35+J35-K35 -> 0
D36: LION | I36: ='[1]1st term 2025'!J23 -> 0 | J36: ='term one 2026'!L37 -> 0 | L36: =I36+J36-K36 -> 0
A37: 30 | B37: 1 | C37: Nakigozi | D37: Brovia | E37: Martha | F37: LION | G37: 1006914417 | I37: ='[1]1st term 2025'!J24 -> 255000 | J37: ='term one 2026'!L38 -> -70000 | K37: =100000+35000+50000 -> 185000 | L37: =I37+J37-K37 -> 0 | M37: f
A38: 31 | B38: 2 | C38: Ssemakula | D38: Joseph | E38: Asher | F38: LION | G38: 1006914745 | I38: ='[1]1st term 2025'!J25+100000 -> 180000 | J38: ='term one 2026'!L39 -> 0 | K38: =180000 -> 180000 | L38: =I38+J38-K38 -> 0 | M38: f
A39: 32 | B39: 3 | C39: Kristian | D39: Pendo | E39: Ogola | F39: LION | G39: 1007134587 | I39: ='[1]1st term 2025'!J27 -> 260000 | J39: ='term one 2026'!L40 -> 0 | K39: =160000+100000 -> 260000 | L39: =I39+J39-K39 -> 0 | M39: f | N39: =L40+L43+#REF!+L44+#REF!+#REF!+#REF! -> #REF!
A40: 33 | B40: 4 | C40: Nakyeyune | D40: Hamnah | E40: Sarah | F40: LION | G40: 1007092280 | I40: ='[1]1st term 2025'!J28 -> 260000 | J40: ='term one 2026'!L41 -> 80000 | K40: =100000+80000+90000 -> 270000 | L40: =I40+J40-K40 -> 70000 | M40: ream
...

Sheet Sheet1
